Workbook

Sheet 🏆 Dashboard
B2: 🏆 BREAKING THE HABIT — DASHBOARD
B4: 🥇 TOP 3 INDIVIDUAL (total c/ transição) | G4: 🏅 TOP 3 DUPLAS (semana atual)
B5: Pos. | C5: Participante | D5: Pts Próprios | E5: Pts Transitados | F5: TOTAL FINAL | G5: Pos. | H5: Dupla | I5: Participantes | J5: Pontos
B6: 🥇 | C6: =IFERROR(INDEX('👤 Ranking Individual'!$C$4:$C$23,MATCH(LARGE('👤 Ranking Individual'!$G$4:$G$23,1),'👤 Ranking Individual'!$G$4:$G$23,0)),"-") -> João Xavier | D6: =IFERROR(INDEX('👤 Ranking Individual'!$E$4:$E$23,MATCH(LARGE('👤 Ranking Individual'!$G$4:$G$23,1),'👤 Ranking Individual'!$G$4:$G$23,0)),0) -> 83 | E6: =IFERROR(INDEX('👤 Ranking Individual'!$F$4:$F$23,MATCH(LARGE('👤 Ranking Individual'!$G$4:$G$23,1),'👤 Ranking Individual'!$G$4:$G$23,0)),0) -> 68 | F6: =IFERROR(LARGE('👤 Ranking Individual'!$G$4:$G$23,1),0) -> 151 | G6: 🥇 | H6: {=IFERROR(INDEX('👥 Ranking Duplas'!$C$7:$C$16,MATCH(LARGE('👥 Ranking Duplas'!$H$7:$H$16,1),'👥 Ranking Duplas'!$H$7:$H$16,0)),"-")} -> Dupla 3 | I6: {=IFERROR(INDEX('👥 Ranking Duplas'!$D$7:$D$16,MATCH(LARGE('👥 Ranking Duplas'!$H$7:$H$16,1),'👥 Ranking Duplas'!$H$7:$H$16,0))&" / "&INDEX('👥 Ranking Duplas'!$E$7:$E$16,MATCH(LARGE('👥 Ranking Duplas'!$H$7:$H$16,1),'👥 Ranking Duplas'!$H$7:$H$16,0)),"-")} -> João Xavier / Rita Carmo | J6: =IFERROR(LARGE('👥 Ranking Duplas'!$H$7:$H$16,1),"-") -> 136
B7: 🥈 | C7: =IFERROR(INDEX('👤 Ranking Individual'!$C$4:$C$23,MATCH(LARGE('👤 Ranking Individual'!$G$4:$G$23,2),'👤 Ranking Individual'!$G$4:$G$23,0)),"-") -> Filipa Cunha | D7: =IFERROR(INDEX('👤 Ranking Individual'!$E$4:$E$23,MATCH(LARGE('👤 Ranking Individual'!$G$4:$G$23,2),'👤 Ranking Individual'!$G$4:$G$23,0)),0) -> 74 | E7: =IFERROR(INDEX('👤 Ranking Individual'!$F$4:$F$23,MATCH(LARGE('👤 Ranking Individual'!$G$4:$G$23,2),'👤 Ranking Individual'!$G$4:$G$23,0)),0) -> 56 | F7: =IFERROR(LARGE('👤 Ranking Individual'!$G$4:$G$23,2),0) -> 130 | G7: 🥈 | H7: {=IFERROR(INDEX('👥 Ranking Duplas'!$C$7:$C$16,MATCH(LARGE('👥 Ranking Duplas'!$H$7:$H$16,2),'👥 Ranking Duplas'!$H$7:$H$16,0)),"-")} -> Dupla 2 | I7: {=IFERROR(INDEX('👥 Ranking Duplas'!$D$7:$D$16,MATCH(LARGE('👥 Ranking Duplas'!$H$7:$H$16,2),'👥 Ranking Duplas'!$H$7:$H$16,0))&" / "&INDEX('👥 Ranking Duplas'!$E$7:$E$16,MATCH(LARGE('👥 Ranking Duplas'!$H$7:$H$16,2),'👥 Ranking Duplas'!$H$7:$H$16,0)),"-")} -> Filipa Cunha / Maria João Travassos | J7: =IFERROR(LARGE('👥 Ranking Duplas'!$H$7:$H$16,2),"-") -> 112
B8: 🥉 | C8: =IFERROR(INDEX('👤 Ranking Individual'!$C$4:$C$23,MATCH(LARGE('👤 Ranking Individual'!$G$4:$G$23,3),'👤 Ranking Individual'!$G$4:$G$23,0)),"-") -> Rita Carmo | D8: =IFERROR(INDEX('👤 Ranking Individual'!$E$4:$E$23,MATCH(LARGE('👤 Ranking Individual'!$G$4:$G$23,3),'👤 Ranking Individual'!$G$4:$G$23,0)),0) -> 53 | E8: =IFERROR(INDEX('👤 Ranking Individual'!$F$4:$F$23,MATCH(LARGE('👤 Ranking Individual'!$G$4:$G$23,3),'👤 Ranking Individual'!$G$4:$G$23,0)),0) -> 68 | F8: =IFERROR(LARGE('👤 Ranking Individual'!$G$4:$G$23,3),0) -> 121 | G8: 🥉 | H8: {=IFERROR(INDEX('👥 Ranking Duplas'!$C$7:$C$16,MATCH(LARGE('👥 Ranking Duplas'!$H$7:$H$16,3),'👥 Ranking Duplas'!$H$7:$H$16,0)),"-")} -> Dupla 4 | I8: {=IFERROR(INDEX('👥 Ranking Duplas'!$D$7:$D$16,MATCH(LARGE('👥 Ranking Duplas'!$H$7:$H$16,3),'👥 Ranking Duplas'!$H$7:$H$16,0))&" / "&INDEX('👥 Ranking Duplas'!$E$7:$E$16,MATCH(LARGE('👥 Ranking Duplas'!$H$7:$H$16,3),'👥 Ranking Duplas'!$H$7:$H$16,0)),"-")} -> Alexandra Correia / William Fernandes | J8: =IFERROR(LARGE('👥 Ranking Duplas'!$H$7:$H$16,3),"-") -> 110
B10: 📈 RESUMO GERAL DO PROGRAMA
B11: Total Contactos | E11: =SUM('📋 Registo Diário'!$E$7:$E$646) -> 451
B12: Total Qualificações | E12: =SUM('📋 Registo Diário'!$F$7:$F$646) -> 101
B13: Total Agendamentos | E13: =SUM('📋 Registo Diário'!$G$7:$G$646) -> 28
B14: Total Reuniões | E14: =SUM('📋 Registo Diário'!$H$7:$H$646) -> 0
B15: Total Propostas | E15: =SUM('📋 Registo Diário'!$I$7:$I$646) -> 0
B16: Total Jokers Usados | E16: =COUNTIF('📋 Registo Diário'!$N$7:$N$646,"S") -> 0
B17: Total Penalizações | E17: =SUM('📋 Registo Diário'!$M$7:$M$646) -> 0
B18: Total Pontos Geral | E18: =SUM('📋 Registo Diário'!$Q$7:$Q$646) -> 793
B20: 💡 Para rankings atualizados ordene a coluna TOTAL em 👤 Ranking Individual e 👥 Ranking Duplas.
B21: 🌟 DESTAQUES DO PROGRAMA
B22: Métrica | C22: Melhor Consultor | D22: Valor | E22: Média Equipa
B23: 🏅 Mais Pontos | C23: =IFERROR(INDEX('👤 Ranking Individual'!$C$4:$C$23,MATCH(MAX('👤 Ranking Individual'!$G$4:$G$23),'👤 Ranking Individual'!$G$4:$G$23,0)),"-") -> João Xavier | D23: =IFERROR(MAX('👤 Ranking Individual'!$G$4:$G$23),0) -> 151 | E23: =IFERROR(ROUND(AVERAGEIF('👤 Ranking Individual'!$G$6:$G$25,">"&0),0),0) -> 92
B24: 📞 Mais Contactos | C24: {=IFERROR(INDEX('👤 Ranking Individual'!$C$4:$C$23,MATCH(MAX(SUMIF('📋 Registo Diário'!$D$7:$D$646,'👤 Ranking Individual'!$C$4:$C$23,'📋 Registo Diário'!$E$7:$E$646)),SUMIF('📋 Registo Diário'!$D$7:$D$646,'👤 Ranking Individual'!$C$4:$C$23,'📋 Registo Diário'!$E$7:$E$646),0)),"-")} -> Filipa Cunha | D24: {=IFERROR(MAX(SUMIF('📋 Registo Diário'!$D$7:$D$646,'👤 Ranking Individual'!$C$4:$C$23,'📋 Registo Diário'!$E$7:$E$646)),0)} -> 46 | E24: =IFERROR(ROUND(AVERAGEIF('📋 Registo Diário'!$E$7:$E$646,">"&0),0),0) -> 14
B25: 🤝 Mais Visitas/ Reuniões | C25: {=IFERROR(INDEX('👤 Ranking Individual'!$C$4:$C$23,MATCH(MAX(SUMIF('📋 Registo Diário'!$D$7:$D$646,'👤 Ranking Individual'!$C$4:$C$23,'📋 Registo Diário'!$H$7:$H$646)),SUMIF('📋 Registo Diário'!$D$7:$D$646,'👤 Ranking Individual'!$C$4:$C$23,'📋 Registo Diário'!$H$7:$H$646),0)),"-")} -> Carla Cantante | D25: {=IFERROR(MAX(SUMIF('📋 Registo Diário'!$D$7:$D$646,'👤 Ranking Individual'!$C$4:$C$23,'📋 Registo Diário'!$H$7:$H$646)),0)} -> 0 | E25: =IFERROR(ROUND(AVERAGEIF('📋 Registo Diário'!$H$7:$H$646,">"&0),0),0) -> 0
B26: 🏠 Mais Propostas | C26: {=IFERROR(INDEX('👤 Ranking Individual'!$C$4:$C$23,MATCH(MAX(SUMIF('📋 Registo Diário'!$D$7:$D$646,'👤 Ranking Individual'!$C$4:$C$23,'📋 Registo Diário'!$I$7:$I$646)),SUMIF('📋 Registo Diário'!$D$7:$D$646,'👤 Ranking Individual'!$C$4:$C$23,'📋 Registo Diário'!$I$7:$I$646),0)),"-")} -> Carla Cantante | D26: {=IFERROR(MAX(SUMIF('📋 Registo Diário'!$D$7:$D$646,'👤 Ranking Individual'!$C$4:$C$23,'📋 Registo Diário'!$I$7:$I$646)),0)} -> 0 | E26: =IFERROR(ROUND(AVERAGEIF('📋 Registo Diário'!$I$7:$I$646,">"&0),0),0) -> 0
B27: 💰 Mais Angariações/Transações | C27: {=IFERROR(INDEX('👤 Ranking Individual'!$C$4:$C$23,MATCH(MAX(SUMIF('📋 Registo Diário'!$D$7:$D$646,'👤 Ranking Individual'!$C$4:$C$23,'📋 Registo Diário'!$J$7:$J$646)),SUMIF('📋 Registo Diário'!$D$7:$D$646,'👤 Ranking Individual'!$C$4:$C$23,'📋 Registo Diário'!$J$7:$J$646),0)),"-")} -> Carla Cantante | D27: {=IFERROR(MAX(SUMIF('📋 Registo Diário'!$D$7:$D$646,'👤 Ranking Individual'!$C$4:$C$23,'📋 Registo Diário'!$J$7:$J$646)),0)} -> 0 | E27: =IFERROR(ROUND(AVERAGEIF('📋 Registo Diário'!$J$7:$J$646,">"&0),0),0) -> 0
B29: 💡 Top 3 e destaques atualizam automaticamente. Para rankings completos ordene as folhas 👤 Ranking Individual e 👥 Ranking Duplas.
B31: 🏆 TOP 5 ACUMULADO INDIVIDUAL | F31: Todas as semanas decorridas | H31: AUX — Pts Semana Atual (ocultar)
B32: Pos. | C32: Participante | D32: Pts Próprios | E32: Pts Transitados | F32: TOTAL | H32: Participante | I32: Pts Sem.
B33: 🥇 | C33: =IFERROR(INDEX('👤 Ranking Individual'!$C$4:$C$23,MATCH(LARGE('👤 Ranking Individual'!$G$4:$G$23,1),'👤 Ranking Individual'!$G$4:$G$23,0)),"-") -> João Xavier | D33: =IFERROR(INDEX('👤 Ranking Individual'!$E$4:$E$23,MATCH(LARGE('👤 Ranking Individual'!$G$4:$G$23,1),'👤 Ranking Individual'!$G$4:$G$23,0)),0) -> 83 | E33: =IFERROR(INDEX('👤 Ranking Individual'!$F$4:$F$23,MATCH(LARGE('👤 Ranking Individual'!$G$4:$G$23,1),'👤 Ranking Individual'!$G$4:$G$23,0)),0) -> 68 | F33: =IFERROR(LARGE('👤 Ranking Individual'!$G$4:$G$23,1),0) -> 151 | H33: ='⚙️ Configuração'!C30 -> Carla Cantante | I33: =SUMIFS('📋 Registo Diário'!$Q$7:$Q$646,'📋 Registo Diário'!$D$7:$D$646,H33,'📋 Registo Diário'!$B$7:$B$646,"Semana "&'⚙️ Configuração'!$H$45) -> 0
B34: 🥈 | C34: =IFERROR(INDEX('👤 Ranking Individual'!$C$4:$C$23,MATCH(LARGE('👤 Ranking Individual'!$G$4:$G$23,2),'👤 Ranking Individual'!$G$4:$G$23,0)),"-") -> Filipa Cunha | D34: =IFERROR(INDEX('👤 Ranking Individual'!$E$4:$E$23,MATCH(LARGE('👤 Ranking Individual'!$G$4:$G$23,2),'👤 Ranking Individual'!$G$4:$G$23,0)),0) -> 74 | E34: =IFERROR(INDEX('👤 Ranking Individual'!$F$4:$F$23,MATCH(LARGE('👤 Ranking Individual'!$G$4:$G$23,2),'👤 Ranking Individual'!$G$4:$G$23,0)),0) -> 56 | F34: =IFERROR(LARGE('👤 Ranking Individual'!$G$4:$G$23,2),0) -> 130 | H34: ='⚙️ Configuração'!C31 -> Elisabete Mendes | I34: =SUMIFS('📋 Registo Diário'!$Q$7:$Q$646,'📋 Registo Diário'!$D$7:$D$646,H34,'📋 Registo Diário'!$B$7:$B$646,"Semana "&'⚙️ Configuração'!$H$45) -> 0
B35: 🥉 | C35: =IFERROR(INDEX('👤 Ranking Individual'!$C$4:$C$23,MATCH(LARGE('👤 Ranking Individual'!$G$4:$G$23,3),'👤 Ranking Individual'!$G$4:$G$23,0)),"-") -> Rita Carmo | D35: =IFERROR(INDEX('👤 Ranking Individual'!$E$4:$E$23,MATCH(LARGE('👤 Ranking Individual'!$G$4:$G$23,3),'👤 Ranking Individual'!$G$4:$G$23,0)),0) -> 53 | E35: =IFERROR(INDEX('👤 Ranking Individual'!$F$4:$F$23,MATCH(LARGE('👤 Ranking Individual'!$G$4:$G$23,3),'👤 Ranking Individual'!$G$4:$G$23,0)),0) -> 68 | F35: =IFERROR(LARGE('👤 Ranking Individual'!$G$4:$G$23,3),0) -> 121 | H35: ='⚙️ Configuração'!C32 -> Filipa Cunha | I35: =SUMIFS('📋 Registo Diário'!$Q$7:$Q$646,'📋 Registo Diário'!$D$7:$D$646,H35,'📋 Registo Diário'!$B$7:$B$646,"Semana "&'⚙️ Configuração'!$H$45) -> 0
B36: 4º | C36: =IFERROR(INDEX('👤 Ranking Individual'!$C$4:$C$23,MATCH(LARGE('👤 Ranking Individual'!$G$4:$G$23,4),'👤 Ranking Individual'!$G$4:$G$23,0)),"-") -> William Fernandes | D36: =IFERROR(INDEX('👤 Ranking Individual'!$E$4:$E$23,MATCH(LARGE('👤 Ranking Individual'!$G$4:$G$23,4),'👤 Ranking Individual'!$G$4:$G$23,0)),0) -> 63 | E36: =IFERROR(INDEX('👤 Ranking Individual'!$F$4:$F$23,MATCH(LARGE('👤 Ranking Individual'!$G$4:$G$23,4),'👤 Ranking Individual'!$G$4:$G$23,0)),0) -> 55 | F36: =IFERROR(LARGE('👤 Ranking Individual'!$G$4:$G$23,4),0) -> 118 | H36: ='⚙️ Configuração'!C33 -> Helena Rocha | I36: =SUMIFS('📋 Registo Diário'!$Q$7:$Q$646,'📋 Registo Diário'!$D$7:$D$646,H36,'📋 Registo Diário'!$B$7:$B$646,"Semana "&'⚙️ Configuração'!$H$45) -> 0
B37: 5º | C37: =IFERROR(INDEX('👤 Ranking Individual'!$C$4:$C$23,MATCH(LARGE('👤 Ranking Individual'!$G$4:$G$23,5),'👤 Ranking Individual'!$G$4:$G$23,0)),"-") -> Alexandra Correia | D37: =IFERROR(INDEX('👤 Ranking Individual'!$E$4:$E$23,MATCH(LARGE('👤 Ranking Individual'!$G$4:$G$23,5),'👤 Ranking Individual'!$G$4:$G$23,0)),0) -> 47 | E37: =IFERROR(INDEX('👤 Ranking Individual'!$F$4:$F$23,MATCH(LARGE('👤 Ranking Individual'!$G$4:$G$23,5),'👤 Ranking Individual'!$G$4:$G$23,0)),0) -> 55 | F37: =IFERROR(LARGE('👤 Ranking Individual'!$G$4:$G$23,5),0) -> 102 | H37: ='⚙️ Configuração'!C34 -> João Xavier | I37: =SUMIFS('📋 Registo Diário'!$Q$7:$Q$646,'📋 Registo Diário'!$D$7:$D$646,H37,'📋 Registo Diário'!$B$7:$B$646,"Semana "&'⚙️ Configuração'!$H$45) -> 0
H38: ='⚙️ Configuração'!C35 -> Tomás Carlos | I38: =SUMIFS('📋 Registo Diário'!$Q$7:$Q$646,'📋 Registo Diário'!$D$7:$D$646,H38,'📋 Registo Diário'!$B$7:$B$646,"Semana "&'⚙️ Configuração'!$H$45) -> 0
H39: ='⚙️ Configuração'!C36 -> Alexandra Correia | I39: =SUMIFS('📋 Registo Diário'!$Q$7:$Q$646,'📋 Registo Diário'!$D$7:$D$646,H39,'📋 Registo Diário'!$B$7:$B$646,"Semana "&'⚙️ Configuração'!$H$45) -> 0
B40: 🔥 TOP 5 SEMANA ATUAL | F40: ="Semana "&'⚙️ Configuração'!H45&" (ajustar em ⚙️ H45)" -> Semana 2 (ajustar em ⚙️ H45) | H40: ='⚙️ Configuração'!C37 -> Carla Barata | I40: =SUMIFS('📋 Registo Diário'!$Q$7:$Q$646,'📋 Registo Diário'!$D$7:$D$646,H40,'📋 Registo Diário'!$B$7:$B$646,"Semana "&'⚙️ Configuração'!$H$45) -> 0
B41: Pos. | C41: Participante | F41: Pontos da Semana | H41: ='⚙️ Configuração'!C38 -> Denise Filipe | I41: =SUMIFS('📋 Registo Diário'!$Q$7:$Q$646,'📋 Registo Diário'!$D$7:$D$646,H41,'📋 Registo Diário'!$B$7:$B$646,"Semana "&'⚙️ Configuração'!$H$45) -> 0
B42: 🥇 | C42: =IFERROR(IF(LARGE($I$33:$I$52,1)=0,"— sem registos —",INDEX($H$33:$H$52,MATCH(LARGE($I$33:$I$52,1),$I$33:$I$52,0))),"-") -> — sem registos — | F42: =IFERROR(LARGE($I$33:$I$52,1),0) -> 0 | H42: ='⚙️ Configuração'!C39 -> Fátima Rodriguez | I42: =SUMIFS('📋 Registo Diário'!$Q$7:$Q$646,'📋 Registo Diário'!$D$7:$D$646,H42,'📋 Registo Diário'!$B$7:$B$646,"Semana "&'⚙️ Configuração'!$H$45) -> 0
B43: 🥈 | C43: =IFERROR(IF(LARGE($I$33:$I$52,2)=0,"—",INDEX($H$33:$H$52,MATCH(LARGE($I$33:$I$52,2),$I$33:$I$52,0))),"-") -> — | F43: =IFERROR(LARGE($I$33:$I$52,2),0) -> 0 | H43: ='⚙️ Configuração'!C40 -> Maria João Travassos | I43: =SUMIFS('📋 Registo Diário'!$Q$7:$Q$646,'📋 Registo Diário'!$D$7:$D$646,H43,'📋 Registo Diário'!$B$7:$B$646,"Semana "&'⚙️ Configuração'!$H$45) -> 0
B44: 🥉 | C44: =IFERROR(IF(LARGE($I$33:$I$52,3)=0,"—",INDEX($H$33:$H$52,MATCH(LARGE($I$33:$I$52,3),$I$33:$I$52,0))),"-") -> — | F44: =IFERROR(LARGE($I$33:$I$52,3),0) -> 0 | H44: ='⚙️ Configuração'!C41 -> Marta Torres | I44: =SUMIFS('📋 Registo Diário'!$Q$7:$Q$646,'📋 Registo Diário'!$D$7:$D$646,H44,'📋 Registo Diário'!$B$7:$B$646,"Semana "&'⚙️ Configuração'!$H$45) -> 0
B45: 4º | C45: =IFERROR(IF(LARGE($I$33:$I$52,4)=0,"—",INDEX($H$33:$H$52,MATCH(LARGE($I$33:$I$52,4),$I$33:$I$52,0))),"-") -> — | F45: =IFERROR(LARGE($I$33:$I$52,4),0) -> 0 | H45: ='⚙️ Configuração'!C42 -> Patricia Isabel Silva | I45: =SUMIFS('📋 Registo Diário'!$Q$7:$Q$646,'📋 Registo Diário'!$D$7:$D$646,H45,'📋 Registo Diário'!$B$7:$B$646,"Semana "&'⚙️ Configuração'!$H$45) -> 0
B46: 5º | C46: =IFERROR(IF(LARGE($I$33:$I$52,5)=0,"—",INDEX($H$33:$H$52,MATCH(LARGE($I$33:$I$52,5),$I$33:$I$52,0))),"-") -> — | F46: =IFERROR(LARGE($I$33:$I$52,5),0) -> 0 | H46: ='⚙️ Configuração'!C43 -> Paula Martins | I46: =SUMIFS('📋 Registo Diário'!$Q$7:$Q$646,'📋 Registo Diário'!$D$7:$D$646,H46,'📋 Registo Diário'!$B$7:$B$646,"Semana "&'⚙️ Configuração'!$H$45) -> 0
...

Sheet ⚙️ Configuração
B2: 🏆 BREAKING THE HABIT — CONFIGURAÇÃO DO PROGRAMA
B4: SISTEMA DE PONTUAÇÃO | G4: DESAFIOS DO PROGRAMA (32)
B5: Atividade | C5: Pontos | D5: Descrição | E5: Multiplicador | G5: Nº | H5: Nome do Desafio | I5: Semana
B6: Contacto Realizado | C6: 1 | D6: Contacto com cliente/prospeto | E6: 1 | G6: 1 | H6: Desafio 1 | I6: Semana 1
B7: Tipo (C/V/A) | C7: 2 | D7: Qualificação: Comprador, Vendedor ou Arrendamento | E7: 1 | G7: 2 | H7: Desafio 2 | I7: Semana 1
B8: Agendamento | C8: 5 | D8: Agendamento de reunião ou visita | E8: 1 | G8: 3 | H8: Desafio 3 | I8: Semana 1
B9: Visita/Reunião | C9: 10 | D9: Visita a imóvel ou reunião com proprietário | E9: 1 | G9: 4 | H9: Desafio 4 | I9: Semana 1
B10: Proposta | C10: 25 | D10: Proposta apresentada ao cliente | E10: 1 | G10: 5 | H10: Desafio 5 | I10: Semana 2
B11: Ang./Transação | C11: 50 | D11: Angariação ou transação concluída | E11: 1 | G11: 6 | H11: Desafio 6 | I11: Semana 2
B12: PENALIZAÇÕES | G12: 7 | H12: Desafio 7 | I12: Semana 2
B13: Tipo | C13: Pontos | D13: Descrição | E13: Código | G13: 8 | H13: Desafio 8 | I13: Semana 2
B14: Atraso até 15 min | C14: -1 | D14: Chegada tardia até 15 minutos | E14: AT1 | G14: 9 | H14: Desafio 9 | I14: Semana 3
B15: Atraso acima 15 min | C15: -2 | D15: Chegada tardia acima de 15 minutos | E15: AT2 | G15: 10 | H15: Desafio 10 | I15: Semana 3
B16: Falta injustificada | C16: -4 | D16: Ausência sem justificação válida | E16: FI | G16: 11 | H16: Desafio 11 | I16: Semana 3
B17: Falta justificada | C17: 0 | D17: Escritura, médico ou força maior | E17: FJ | G17: 12 | H17: Desafio 12 | I17: Semana 3
G18: 13 | H18: Desafio 13 | I18: Semana 4
B19: PONTUAÇÃO EXTRA DIÁRIA (POR DUPLA) | G19: 14 | H19: Desafio 14 | I19: Semana 4
B20: Lugar | C20: Pontos Extra | D20: Descrição | G20: 15 | H20: Desafio 15 | I20: Semana 4
B21: 1º Lugar | C21: 10 | D21: Dupla com mais pontos no desafio do dia | G21: 16 | H21: Desafio 16 | I21: Semana 4
B22: 2º Lugar | C22: 6 | D22: Segunda dupla com mais pontos | G22: 17 | H22: Desafio 17 | I22: Semana 5
B23: 3º Lugar | C23: 4 | D23: Terceira dupla com mais pontos | G23: 18 | H23: Desafio 18 | I23: Semana 5
B24: Restantes | C24: 2 | D24: Duplas que cumpriram o desafio | G24: 19 | H24: Desafio 19 | I24: Semana 5
G25: 20 | H25: Desafio 20 | I25: Semana 5
B26: ⚠️ Células amarelas são editáveis — alterações refletem-se em todo o ficheiro | G26: 21 | H26: Desafio 21 | I26: Semana 6
G27: 22 | H27: Desafio 22 | I27: Semana 6
B28: PARTICIPANTES (nomes editáveis) | G28: 23 | H28: Desafio 23 | I28: Semana 6
B29: Nº | C29: Nome Participante | D29: Nº Ref. | E29: Código | G29: 24 | H29: Desafio 24 | I29: Semana 6
B30: 1 | C30: Carla Cantante | D30: 1 | E30: P01 | G30: 25 | H30: Desafio 25 | I30: Semana 7
B31: 2 | C31: Elisabete Mendes | D31: 2 | E31: P02 | G31: 26 | H31: Desafio 26 | I31: Semana 7
B32: 3 | C32: Filipa Cunha | D32: 3 | E32: P03 | G32: 27 | H32: Desafio 27 | I32: Semana 7
B33: 4 | C33: Helena Rocha | D33: 4 | E33: P04 | G33: 28 | H33: Desafio 28 | I33: Semana 7
B34: 5 | C34: João Xavier | D34: 5 | E34: P05 | G34: 29 | H34: Desafio 29 | I34: Semana 8
B35: 6 | C35: Tomás Carlos | D35: 6 | E35: P06 | G35: 30 | H35: Desafio 30 | I35: Semana 8
B36: 7 | C36: Alexandra Correia | D36: 7 | E36: P07 | G36: 31 | H36: Desafio 31 | I36: Semana 8
B37: 8 | C37: Carla Barata | D37: 8 | E37: P08 | G37: 32 | H37: Desafio 32 | I37: Semana 8
B38: 9 | C38: Denise Filipe | D38: 9 | E38: P09 | G38: PARÂMETROS DO PROGRAMA
B39: 10 | C39: Fátima Rodriguez | D39: 10 | E39: P10 | G39: Duração (dias) | H39: 60
B40: 11 | C40: Maria João Travassos | D40: 11 | E40: P11 | G40: Nº Desafios | H40: 32
B41: 12 | C41: Marta Torres | D41: 12 | E41: P12 | G41: Nº Participantes | H41: 17
B42: 13 | C42: Patricia Isabel Silva | D42: 13 | E42: P13 | G42: Nº Duplas por semana | H42: 8
...

Sheet 🔄 Rotação Duplas
B2: 🔄 BREAKING THE HABIT — ROTAÇÃO SEMANAL DE DUPLAS
B4: 📝 Semana 1 pré-preenchida com pares iniciais. Para as semanas seguintes, selecione os nomes via dropdown (células amarelas) — os nomes vêm automaticamente da Configuração. 🔴 Alerta vermelho = participante repetido na mesma dupla.
B6: SEMANA 1
B7: Dupla | C7: Participante 1 | D7: Participante 2 | E7: Pts P1 (semana) | F7: Pts P2 (semana) | G7: Total Dupla | H7: Transição P1 (÷2) | I7: Transição P2 (÷2)
B8: 1 | C8: ='⚙️ Configuração'!C30 -> Carla Cantante | D8: ='⚙️ Configuração'!C38 -> Denise Filipe | E8: =IF(C8="","-",SUMIFS('📋 Registo Diário'!$Q$7:$Q$646,'📋 Registo Diário'!$D$7:$D$646,C8,'📋 Registo Diário'!$B$7:$B$646,"Semana 1")) -> 45 | F8: =IF(D8="","-",SUMIFS('📋 Registo Diário'!$Q$7:$Q$646,'📋 Registo Diário'!$D$7:$D$646,D8,'📋 Registo Diário'!$B$7:$B$646,"Semana 1")) -> 42 | G8: =IF(OR(E8="-",F8="-"),"-",E8+F8) -> 87 | H8: =IF(G8="-","-",INT(G8/2)) -> 43 | I8: =IF(G8="-","-",G8-INT(G8/2)) -> 44
B9: 2 | C9: ='⚙️ Configuração'!C32 -> Filipa Cunha | D9: ='⚙️ Configuração'!C40 -> Maria João Travassos | E9: =IF(C9="","-",SUMIFS('📋 Registo Diário'!$Q$7:$Q$646,'📋 Registo Diário'!$D$7:$D$646,C9,'📋 Registo Diário'!$B$7:$B$646,"Semana 1")) -> 74 | F9: =IF(D9="","-",SUMIFS('📋 Registo Diário'!$Q$7:$Q$646,'📋 Registo Diário'!$D$7:$D$646,D9,'📋 Registo Diário'!$B$7:$B$646,"Semana 1")) -> 38 | G9: =IF(OR(E9="-",F9="-"),"-",E9+F9) -> 112 | H9: =IF(G9="-","-",INT(G9/2)) -> 56 | I9: =IF(G9="-","-",G9-INT(G9/2)) -> 56
B10: 3 | C10: ='⚙️ Configuração'!C34 -> João Xavier | D10: ='⚙️ Configuração'!C45 -> Rita Carmo | E10: =IF(C10="","-",SUMIFS('📋 Registo Diário'!$Q$7:$Q$646,'📋 Registo Diário'!$D$7:$D$646,C10,'📋 Registo Diário'!$B$7:$B$646,"Semana 1")) -> 83 | F10: =IF(D10="","-",SUMIFS('📋 Registo Diário'!$Q$7:$Q$646,'📋 Registo Diário'!$D$7:$D$646,D10,'📋 Registo Diário'!$B$7:$B$646,"Semana 1")) -> 53 | G10: =IF(OR(E10="-",F10="-"),"-",E10+F10) -> 136 | H10: =IF(G10="-","-",INT(G10/2)) -> 68 | I10: =IF(G10="-","-",G10-INT(G10/2)) -> 68
B11: 4 | C11: ='⚙️ Configuração'!C36 -> Alexandra Correia | D11: ='⚙️ Configuração'!C46 -> William Fernandes | E11: =IF(C11="","-",SUMIFS('📋 Registo Diário'!$Q$7:$Q$646,'📋 Registo Diário'!$D$7:$D$646,C11,'📋 Registo Diário'!$B$7:$B$646,"Semana 1")) -> 47 | F11: =IF(D11="","-",SUMIFS('📋 Registo Diário'!$Q$7:$Q$646,'📋 Registo Diário'!$D$7:$D$646,D11,'📋 Registo Diário'!$B$7:$B$646,"Semana 1")) -> 63 | G11: =IF(OR(E11="-",F11="-"),"-",E11+F11) -> 110 | H11: =IF(G11="-","-",INT(G11/2)) -> 55 | I11: =IF(G11="-","-",G11-INT(G11/2)) -> 55
B12: 5 | D12: ='⚙️ Configuração'!C39 -> Fátima Rodriguez | E12: =IF(C12="","-",SUMIFS('📋 Registo Diário'!$Q$7:$Q$646,'📋 Registo Diário'!$D$7:$D$646,C12,'📋 Registo Diário'!$B$7:$B$646,"Semana 1")) -> - | F12: =IF(D12="","-",SUMIFS('📋 Registo Diário'!$Q$7:$Q$646,'📋 Registo Diário'!$D$7:$D$646,D12,'📋 Registo Diário'!$B$7:$B$646,"Semana 1")) -> 69 | G12: =IF(OR(E12="-",F12="-"),"-",E12+F12) -> - | H12: =IF(G12="-","-",INT(G12/2)) -> - | I12: =IF(G12="-","-",G12-INT(G12/2)) -> -
B13: 6 | C13: ='⚙️ Configuração'!C44 -> Paula Miabara | D13: ='⚙️ Configuração'!C41 -> Marta Torres | E13: =IF(C13="","-",SUMIFS('📋 Registo Diário'!$Q$7:$Q$646,'📋 Registo Diário'!$D$7:$D$646,C13,'📋 Registo Diário'!$B$7:$B$646,"Semana 1")) -> 28 | F13: =IF(D13="","-",SUMIFS('📋 Registo Diário'!$Q$7:$Q$646,'📋 Registo Diário'!$D$7:$D$646,D13,'📋 Registo Diário'!$B$7:$B$646,"Semana 1")) -> 54 | G13: =IF(OR(E13="-",F13="-"),"-",E13+F13) -> 82 | H13: =IF(G13="-","-",INT(G13/2)) -> 41 | I13: =IF(G13="-","-",G13-INT(G13/2)) -> 41
B14: 7 | C14: ='⚙️ Configuração'!C42 -> Patricia Isabel Silva | D14: ='⚙️ Configuração'!C35 -> Tomás Carlos | E14: =IF(C14="","-",SUMIFS('📋 Registo Diário'!$Q$7:$Q$646,'📋 Registo Diário'!$D$7:$D$646,C14,'📋 Registo Diário'!$B$7:$B$646,"Semana 1")) -> 41 | F14: =IF(D14="","-",SUMIFS('📋 Registo Diário'!$Q$7:$Q$646,'📋 Registo Diário'!$D$7:$D$646,D14,'📋 Registo Diário'!$B$7:$B$646,"Semana 1")) -> 50 | G14: =IF(OR(E14="-",F14="-"),"-",E14+F14) -> 91 | H14: =IF(G14="-","-",INT(G14/2)) -> 45 | I14: =IF(G14="-","-",G14-INT(G14/2)) -> 46
B15: 8 | C15: ='⚙️ Configuração'!C37 -> Carla Barata | D15: ='⚙️ Configuração'!C43 -> Paula Martins | E15: =IF(C15="","-",SUMIFS('📋 Registo Diário'!$Q$7:$Q$646,'📋 Registo Diário'!$D$7:$D$646,C15,'📋 Registo Diário'!$B$7:$B$646,"Semana 1")) -> 23 | F15: =IF(D15="","-",SUMIFS('📋 Registo Diário'!$Q$7:$Q$646,'📋 Registo Diário'!$D$7:$D$646,D15,'📋 Registo Diário'!$B$7:$B$646,"Semana 1")) -> 20 | G15: =IF(OR(E15="-",F15="-"),"-",E15+F15) -> 43 | H15: =IF(G15="-","-",INT(G15/2)) -> 21 | I15: =IF(G15="-","-",G15-INT(G15/2)) -> 22
B16: 9 | C16: ='⚙️ Configuração'!C31 -> Elisabete Mendes | D16: ='⚙️ Configuração'!C33 -> Helena Rocha | E16: =IF(C16="","-",SUMIFS('📋 Registo Diário'!$Q$7:$Q$646,'📋 Registo Diário'!$D$7:$D$646,C16,'📋 Registo Diário'!$B$7:$B$646,"Semana 1")) -> 23 | F16: =IF(D16="","-",SUMIFS('📋 Registo Diário'!$Q$7:$Q$646,'📋 Registo Diário'!$D$7:$D$646,D16,'📋 Registo Diário'!$B$7:$B$646,"Semana 1")) -> 40 | G16: =IF(OR(E16="-",F16="-"),"-",E16+F16) -> 63 | H16: =IF(G16="-","-",INT(G16/2)) -> 31 | I16: =IF(G16="-","-",G16-INT(G16/2)) -> 32
B17: 10 | C17: ='⚙️ Configuração'!C48 -> - | D17: ='⚙️ Configuração'!C49 -> - | E17: =IF(C17="","-",SUMIFS('📋 Registo Diário'!$Q$7:$Q$646,'📋 Registo Diário'!$D$7:$D$646,C17,'📋 Registo Diário'!$B$7:$B$646,"Semana 1")) -> 0 | F17: =IF(D17="","-",SUMIFS('📋 Registo Diário'!$Q$7:$Q$646,'📋 Registo Diário'!$D$7:$D$646,D17,'📋 Registo Diário'!$B$7:$B$646,"Semana 1")) -> 0 | G17: =IF(OR(E17="-",F17="-"),"-",E17+F17) -> 0 | H17: =IF(G17="-","-",INT(G17/2)) -> 0 | I17: =IF(G17="-","-",G17-INT(G17/2)) -> 0
B18: Totais Semana 1 | E18: Total pontos gerados na semana → | G18: =IF(G8="-",0,G8)+IF(G9="-",0,G9)+IF(G10="-",0,G10)+IF(G11="-",0,G11)+IF(G12="-",0,G12)+IF(G13="-",0,G13)+IF(G14="-",0,G14)+IF(G15="-",0,G15)+IF(G16="-",0,G16)+IF(G17="-",0,G17) -> 724
B20: SEMANA 2
B21: Dupla | C21: Participante 1 | D21: Participante 2 | E21: Pts P1 (semana) | F21: Pts P2 (semana) | G21: Total Dupla | H21: Transição P1 (÷2) | I21: Transição P2 (÷2)
B22: 1 | E22: =IF(C22="","-",SUMIFS('📋 Registo Diário'!$Q$7:$Q$646,'📋 Registo Diário'!$D$7:$D$646,C22,'📋 Registo Diário'!$B$7:$B$646,"Semana 2")) -> - | F22: =IF(D22="","-",SUMIFS('📋 Registo Diário'!$Q$7:$Q$646,'📋 Registo Diário'!$D$7:$D$646,D22,'📋 Registo Diário'!$B$7:$B$646,"Semana 2")) -> - | G22: =IF(OR(E22="-",F22="-"),"-",E22+F22) -> - | H22: =IF(G22="-","-",INT(G22/2)) -> - | I22: =IF(G22="-","-",G22-INT(G22/2)) -> -
B23: 2 | E23: =IF(C23="","-",SUMIFS('📋 Registo Diário'!$Q$7:$Q$646,'📋 Registo Diário'!$D$7:$D$646,C23,'📋 Registo Diário'!$B$7:$B$646,"Semana 2")) -> - | F23: =IF(D23="","-",SUMIFS('📋 Registo Diário'!$Q$7:$Q$646,'📋 Registo Diário'!$D$7:$D$646,D23,'📋 Registo Diário'!$B$7:$B$646,"Semana 2")) -> - | G23: =IF(OR(E23="-",F23="-"),"-",E23+F23) -> - | H23: =IF(G23="-","-",INT(G23/2)) -> - | I23: =IF(G23="-","-",G23-INT(G23/2)) -> -
B24: 3 | E24: =IF(C24="","-",SUMIFS('📋 Registo Diário'!$Q$7:$Q$646,'📋 Registo Diário'!$D$7:$D$646,C24,'📋 Registo Diário'!$B$7:$B$646,"Semana 2")) -> - | F24: =IF(D24="","-",SUMIFS('📋 Registo Diário'!$Q$7:$Q$646,'📋 Registo Diário'!$D$7:$D$646,D24,'📋 Registo Diário'!$B$7:$B$646,"Semana 2")) -> - | G24: =IF(OR(E24="-",F24="-"),"-",E24+F24) -> - | H24: =IF(G24="-","-",INT(G24/2)) -> - | I24: =IF(G24="-","-",G24-INT(G24/2)) -> -
B25: 4 | E25: =IF(C25="","-",SUMIFS('📋 Registo Diário'!$Q$7:$Q$646,'📋 Registo Diário'!$D$7:$D$646,C25,'📋 Registo Diário'!$B$7:$B$646,"Semana 2")) -> - | F25: =IF(D25="","-",SUMIFS('📋 Registo Diário'!$Q$7:$Q$646,'📋 Registo Diário'!$D$7:$D$646,D25,'📋 Registo Diário'!$B$7:$B$646,"Semana 2")) -> - | G25: =IF(OR(E25="-",F25="-"),"-",E25+F25) -> - | H25: =IF(G25="-","-",INT(G25/2)) -> - | I25: =IF(G25="-","-",G25-INT(G25/2)) -> -
B26: 5 | E26: =IF(C26="","-",SUMIFS('📋 Registo Diário'!$Q$7:$Q$646,'📋 Registo Diário'!$D$7:$D$646,C26,'📋 Registo Diário'!$B$7:$B$646,"Semana 2")) -> - | F26: =IF(D26="","-",SUMIFS('📋 Registo Diário'!$Q$7:$Q$646,'📋 Registo Diário'!$D$7:$D$646,D26,'📋 Registo Diário'!$B$7:$B$646,"Semana 2")) -> - | G26: =IF(OR(E26="-",F26="-"),"-",E26+F26) -> - | H26: =IF(G26="-","-",INT(G26/2)) -> - | I26: =IF(G26="-","-",G26-INT(G26/2)) -> -
B27: 6 | E27: =IF(C27="","-",SUMIFS('📋 Registo Diário'!$Q$7:$Q$646,'📋 Registo Diário'!$D$7:$D$646,C27,'📋 Registo Diário'!$B$7:$B$646,"Semana 2")) -> - | F27: =IF(D27="","-",SUMIFS('📋 Registo Diário'!$Q$7:$Q$646,'📋 Registo Diário'!$D$7:$D$646,D27,'📋 Registo Diário'!$B$7:$B$646,"Semana 2")) -> - | G27: =IF(OR(E27="-",F27="-"),"-",E27+F27) -> - | H27: =IF(G27="-","-",INT(G27/2)) -> - | I27: =IF(G27="-","-",G27-INT(G27/2)) -> -
B28: 7 | E28: =IF(C28="","-",SUMIFS('📋 Registo Diário'!$Q$7:$Q$646,'📋 Registo Diário'!$D$7:$D$646,C28,'📋 Registo Diário'!$B$7:$B$646,"Semana 2")) -> - | F28: =IF(D28="","-",SUMIFS('📋 Registo Diário'!$Q$7:$Q$646,'📋 Registo Diário'!$D$7:$D$646,D28,'📋 Registo Diário'!$B$7:$B$646,"Semana 2")) -> - | G28: =IF(OR(E28="-",F28="-"),"-",E28+F28) -> - | H28: =IF(G28="-","-",INT(G28/2)) -> - | I28: =IF(G28="-","-",G28-INT(G28/2)) -> -
B29: 8 | E29: =IF(C29="","-",SUMIFS('📋 Registo Diário'!$Q$7:$Q$646,'📋 Registo Diário'!$D$7:$D$646,C29,'📋 Registo Diário'!$B$7:$B$646,"Semana 2")) -> - | F29: =IF(D29="","-",SUMIFS('📋 Registo Diário'!$Q$7:$Q$646,'📋 Registo Diário'!$D$7:$D$646,D29,'📋 Registo Diário'!$B$7:$B$646,"Semana 2")) -> - | G29: =IF(OR(E29="-",F29="-"),"-",E29+F29) -> - | H29: =IF(G29="-","-",INT(G29/2)) -> - | I29: =IF(G29="-","-",G29-INT(G29/2)) -> -
B30: 9 | E30: =IF(C30="","-",SUMIFS('📋 Registo Diário'!$Q$7:$Q$646,'📋 Registo Diário'!$D$7:$D$646,C30,'📋 Registo Diário'!$B$7:$B$646,"Semana 2")) -> - | F30: =IF(D30="","-",SUMIFS('📋 Registo Diário'!$Q$7:$Q$646,'📋 Registo Diário'!$D$7:$D$646,D30,'📋 Registo Diário'!$B$7:$B$646,"Semana 2")) -> - | G30: =IF(OR(E30="-",F30="-"),"-",E30+F30) -> - | H30: =IF(G30="-","-",INT(G30/2)) -> - | I30: =IF(G30="-","-",G30-INT(G30/2)) -> -
B31: 10 | E31: =IF(C31="","-",SUMIFS('📋 Registo Diário'!$Q$7:$Q$646,'📋 Registo Diário'!$D$7:$D$646,C31,'📋 Registo Diário'!$B$7:$B$646,"Semana 2")) -> - | F31: =IF(D31="","-",SUMIFS('📋 Registo Diário'!$Q$7:$Q$646,'📋 Registo Diário'!$D$7:$D$646,D31,'📋 Registo Diário'!$B$7:$B$646,"Semana 2")) -> - | G31: =IF(OR(E31="-",F31="-"),"-",E31+F31) -> - | H31: =IF(G31="-","-",INT(G31/2)) -> - | I31: =IF(G31="-","-",G31-INT(G31/2)) -> -
B32: Totais Semana 2 | E32: Total pontos gerados na semana → | G32: =IF(G22="-",0,G22)+IF(G23="-",0,G23)+IF(G24="-",0,G24)+IF(G25="-",0,G25)+IF(G26="-",0,G26)+IF(G27="-",0,G27)+IF(G28="-",0,G28)+IF(G29="-",0,G29)+IF(G30="-",0,G30)+IF(G31="-",0,G31) -> 0
B34: SEMANA 3
B35: Dupla | C35: Participante 1 | D35: Participante 2 | E35: Pts P1 (semana) | F35: Pts P2 (semana) | G35: Total Dupla | H35: Transição P1 (÷2) | I35: Transição P2 (÷2)
B36: 1 | E36: =IF(C36="","-",SUMIFS('📋 Registo Diário'!$Q$7:$Q$646,'📋 Registo Diário'!$D$7:$D$646,C36,'📋 Registo Diário'!$B$7:$B$646,"Semana 3")) -> - | F36: =IF(D36="","-",SUMIFS('📋 Registo Diário'!$Q$7:$Q$646,'📋 Registo Diário'!$D$7:$D$646,D36,'📋 Registo Diário'!$B$7:$B$646,"Semana 3")) -> - | G36: =IF(OR(E36="-",F36="-"),"-",E36+F36) -> - | H36: =IF(G36="-","-",INT(G36/2)) -> - | I36: =IF(G36="-","-",G36-INT(G36/2)) -> -
B37: 2 | E37: =IF(C37="","-",SUMIFS('📋 Registo Diário'!$Q$7:$Q$646,'📋 Registo Diário'!$D$7:$D$646,C37,'📋 Registo Diário'!$B$7:$B$646,"Semana 3")) -> - | F37: =IF(D37="","-",SUMIFS('📋 Registo Diário'!$Q$7:$Q$646,'📋 Registo Diário'!$D$7:$D$646,D37,'📋 Registo Diário'!$B$7:$B$646,"Semana 3")) -> - | G37: =IF(OR(E37="-",F37="-"),"-",E37+F37) -> - | H37: =IF(G37="-","-",INT(G37/2)) -> - | I37: =IF(G37="-","-",G37-INT(G37/2)) -> -
B38: 3 | E38: =IF(C38="","-",SUMIFS('📋 Registo Diário'!$Q$7:$Q$646,'📋 Registo Diário'!$D$7:$D$646,C38,'📋 Registo Diário'!$B$7:$B$646,"Semana 3")) -> - | F38: =IF(D38="","-",SUMIFS('📋 Registo Diário'!$Q$7:$Q$646,'📋 Registo Diário'!$D$7:$D$646,D38,'📋 Registo Diário'!$B$7:$B$646,"Semana 3")) -> - | G38: =IF(OR(E38="-",F38="-"),"-",E38+F38) -> - | H38: =IF(G38="-","-",INT(G38/2)) -> - | I38: =IF(G38="-","-",G38-INT(G38/2)) -> -
B39: 4 | E39: =IF(C39="","-",SUMIFS('📋 Registo Diário'!$Q$7:$Q$646,'📋 Registo Diário'!$D$7:$D$646,C39,'📋 Registo Diário'!$B$7:$B$646,"Semana 3")) -> - | F39: =IF(D39="","-",SUMIFS('📋 Registo Diário'!$Q$7:$Q$646,'📋 Registo Diário'!$D$7:$D$646,D39,'📋 Registo Diário'!$B$7:$B$646,"Semana 3")) -> - | G39: =IF(OR(E39="-",F39="-"),"-",E39+F39) -> - | H39: =IF(G39="-","-",INT(G39/2)) -> - | I39: =IF(G39="-","-",G39-INT(G39/2)) -> -
B40: 5 | E40: =IF(C40="","-",SUMIFS('📋 Registo Diário'!$Q$7:$Q$646,'📋 Registo Diário'!$D$7:$D$646,C40,'📋 Registo Diário'!$B$7:$B$646,"Semana 3")) -> - | F40: =IF(D40="","-",SUMIFS('📋 Registo Diário'!$Q$7:$Q$646,'📋 Registo Diário'!$D$7:$D$646,D40,'📋 Registo Diário'!$B$7:$B$646,"Semana 3")) -> - | G40: =IF(OR(E40="-",F40="-"),"-",E40+F40) -> - | H40: =IF(G40="-","-",INT(G40/2)) -> - | I40: =IF(G40="-","-",G40-INT(G40/2)) -> -
B41: 6 | E41: =IF(C41="","-",SUMIFS('📋 Registo Diário'!$Q$7:$Q$646,'📋 Registo Diário'!$D$7:$D$646,C41,'📋 Registo Diário'!$B$7:$B$646,"Semana 3")) -> - | F41: =IF(D41="","-",SUMIFS('📋 Registo Diário'!$Q$7:$Q$646,'📋 Registo Diário'!$D$7:$D$646,D41,'📋 Registo Diário'!$B$7:$B$646,"Semana 3")) -> - | G41: =IF(OR(E41="-",F41="-"),"-",E41+F41) -> - | H41: =IF(G41="-","-",INT(G41/2)) -> - | I41: =IF(G41="-","-",G41-INT(G41/2)) -> -
B42: 7 | E42: =IF(C42="","-",SUMIFS('📋 Registo Diário'!$Q$7:$Q$646,'📋 Registo Diário'!$D$7:$D$646,C42,'📋 Registo Diário'!$B$7:$B$646,"Semana 3")) -> - | F42: =IF(D42="","-",SUMIFS('📋 Registo Diário'!$Q$7:$Q$646,'📋 Registo Diário'!$D$7:$D$646,D42,'📋 Registo Diário'!$B$7:$B$646,"Semana 3")) -> - | G42: =IF(OR(E42="-",F42="-"),"-",E42+F42) -> - | H42: =IF(G42="-","-",INT(G42/2)) -> - | I42: =IF(G42="-","-",G42-INT(G42/2)) -> -
B43: 8 | E43: =IF(C43="","-",SUMIFS('📋 Registo Diário'!$Q$7:$Q$646,'📋 Registo Diário'!$D$7:$D$646,C43,'📋 Registo Diário'!$B$7:$B$646,"Semana 3")) -> - | F43: =IF(D43="","-",SUMIFS('📋 Registo Diário'!$Q$7:$Q$646,'📋 Registo Diário'!$D$7:$D$646,D43,'📋 Registo Diário'!$B$7:$B$646,"Semana 3")) -> - | G43: =IF(OR(E43="-",F43="-"),"-",E43+F43) -> - | H43: =IF(G43="-","-",INT(G43/2)) -> - | I43: =IF(G43="-","-",G43-INT(G43/2)) -> -
B44: 9 | E44: =IF(C44="","-",SUMIFS('📋 Registo Diário'!$Q$7:$Q$646,'📋 Registo Diário'!$D$7:$D$646,C44,'📋 Registo Diário'!$B$7:$B$646,"Semana 3")) -> - | F44: =IF(D44="","-",SUMIFS('📋 Registo Diário'!$Q$7:$Q$646,'📋 Registo Diário'!$D$7:$D$646,D44,'📋 Registo Diário'!$B$7:$B$646,"Semana 3")) -> - | G44: =IF(OR(E44="-",F44="-"),"-",E44+F44) -> - | H44: =IF(G44="-","-",INT(G44/2)) -> - | I44: =IF(G44="-","-",G44-INT(G44/2)) -> -
B45: 10 | E45: =IF(C45="","-",SUMIFS('📋 Registo Diário'!$Q$7:$Q$646,'📋 Registo Diário'!$D$7:$D$646,C45,'📋 Registo Diário'!$B$7:$B$646,"Semana 3")) -> - | F45: =IF(D45="","-",SUMIFS('📋 Registo Diário'!$Q$7:$Q$646,'📋 Registo Diário'!$D$7:$D$646,D45,'📋 Registo Diário'!$B$7:$B$646,"Semana 3")) -> - | G45: =IF(OR(E45="-",F45="-"),"-",E45+F45) -> - | H45: =IF(G45="-","-",INT(G45/2)) -> - | I45: =IF(G45="-","-",G45-INT(G45/2)) -> -
...

Sheet 💱 Pontos Transitados
B2: 💱 BREAKING THE HABIT — PONTOS TRANSITADOS (AUTO)
B4: ✅ Esta folha é 100% automática — calcula os pontos transitados de cada participante diretamente da folha 🔄 Rotação Duplas. Não é necessário qualquer preenchimento manual. Os valores atualizam automaticamente quando as duplas da Rotação são definidas.
B5: Participante | C5: Transitado Sem. 1 | D5: Transitado Sem. 2 | E5: Transitado Sem. 3 | F5: Transitado Sem. 4 | G5: Transitado Sem. 5 | H5: Transitado Sem. 6 | I5: Transitado Sem. 7 | J5: Transitado Sem. 8 | K5: Total Transitado | L5: Pts Próprios (Registo) | M5: TOTAL FINAL
B6: ='⚙️ Configuração'!C30 -> Carla Cantante | C6: =IF('⚙️ Configuração'!C30='🔄 Rotação Duplas'!C8,IF('🔄 Rotação Duplas'!H8="-",0,'🔄 Rotação Duplas'!H8),IF('⚙️ Configuração'!C30='🔄 Rotação Duplas'!D8,IF('🔄 Rotação Duplas'!I8="-",0,'🔄 Rotação Duplas'!I8),0))+IF('⚙️ Configuração'!C30='🔄 Rotação Duplas'!C9,IF('🔄 Rotação Duplas'!H9="-",0,'🔄 Rotação Duplas'!H9),IF('⚙️ Configuração'!C30='🔄 Rotação Duplas'!D9,IF('🔄 Rotação Duplas'!I9="-",0,'🔄 Rotação Duplas'!I9),0))+IF('⚙️ Configuração'!C30='🔄 Rotação Duplas'!C10,IF('🔄 Rotação Duplas'!H10="-",0,'🔄 Rotação Duplas'!H10),IF('⚙️ Configuração'!C30='🔄 Rotação Duplas'!D10,IF('🔄 Rotação Duplas'!I10="-",0,'🔄 Rotação Duplas'!I10),0))+IF('⚙️ Configuração'!C30='🔄 Rotação Duplas'!C11,IF('🔄 Rotação Duplas'!H11="-",0,'🔄 Rotação Duplas'!H11),IF('⚙️ Configuração'!C30='🔄 Rotação Duplas'!D11,IF('🔄 Rotação Duplas'!I11="-",0,'🔄 Rotação Duplas'!I11),0))+IF('⚙️ Configuração'!C30='🔄 Rotação Duplas'!C12,IF('🔄 Rotação Duplas'!H12="-",0,'🔄 Rotação Duplas'!H12),IF('⚙️ Configuração'!C30='🔄 Rotação Duplas'!D12,IF('🔄 Rotação Duplas'!I12="-",0,'🔄 Rotação Duplas'!I12),0))+IF('⚙️ Configuração'!C30='🔄 Rotação Duplas'!C13,IF('🔄 Rotação Duplas'!H13="-",0,'🔄 Rotação Duplas'!H13),IF('⚙️ Configuração'!C30='🔄 Rotação Duplas'!D13,IF('🔄 Rotação Duplas'!I13="-",0,'🔄 Rotação Duplas'!I13),0))+IF('⚙️ Configuração'!C30='🔄 Rotação Duplas'!C14,IF('🔄 Rotação Duplas'!H14="-",0,'🔄 Rotação Duplas'!H14),IF('⚙️ Configuração'!C30='🔄 Rotação Duplas'!D14,IF('🔄 Rotação Duplas'!I14="-",0,'🔄 Rotação Duplas'!I14),0))+IF('⚙️ Configuração'!C30='🔄 Rotação Duplas'!C15,IF('🔄 Rotação Duplas'!H15="-",0,'🔄 Rotação Duplas'!H15),IF('⚙️ Configuração'!C30='🔄 Rotação Duplas'!D15,IF('🔄 Rotação Duplas'!I15="-",0,'🔄 Rotação Duplas'!I15),0))+IF('⚙️ Configuração'!C30='🔄 Rotação Duplas'!C16,IF('🔄 Rotação Duplas'!H16="-",0,'🔄 Rotação Duplas'!H16),IF('⚙️ Configuração'!C30='🔄 Rotação Duplas'!D16,IF('🔄 Rotação Duplas'!I16="-",0,'🔄 Rotação Duplas'!I16),0))+IF('⚙️ Configuração'!C30='🔄 Rotação Duplas'!C17,IF('🔄 Rotação Duplas'!H17="-",0,'🔄 Rotação Duplas'!H17),IF('⚙️ Configuração'!C30='🔄 Rotação Duplas'!D17,IF('🔄 Rotação Duplas'!I17="-",0,'🔄 Rotação Duplas'!I17),0)) -> 43 | D6: =IF('⚙️ Configuração'!C30='🔄 Rotação Duplas'!C22,IF('🔄 Rotação Duplas'!H22="-",0,'🔄 Rotação Duplas'!H22),IF('⚙️ Configuração'!C30='🔄 Rotação Duplas'!D22,IF('🔄 Rotação Duplas'!I22="-",0,'🔄 Rotação Duplas'!I22),0))+IF('⚙️ Configuração'!C30='🔄 Rotação Duplas'!C23,IF('🔄 Rotação Duplas'!H23="-",0,'🔄 Rotação Duplas'!H23),IF('⚙️ Configuração'!C30='🔄 Rotação Duplas'!D23,IF('🔄 Rotação Duplas'!I23="-",0,'🔄 Rotação Duplas'!I23),0))+IF('⚙️ Configuração'!C30='🔄 Rotação Duplas'!C24,IF('🔄 Rotação Duplas'!H24="-",0,'🔄 Rotação Duplas'!H24),IF('⚙️ Configuração'!C30='🔄 Rotação Duplas'!D24,IF('🔄 Rotação Duplas'!I24="-",0,'🔄 Rotação Duplas'!I24),0))+IF('⚙️ Configuração'!C30='🔄 Rotação Duplas'!C25,IF('🔄 Rotação Duplas'!H25="-",0,'🔄 Rotação Duplas'!H25),IF('⚙️ Configuração'!C30='🔄 Rotação Duplas'!D25,IF('🔄 Rotação Duplas'!I25="-",0,'🔄 Rotação Duplas'!I25),0))+IF('⚙️ Configuração'!C30='🔄 Rotação Duplas'!C26,IF('🔄 Rotação Duplas'!H26="-",0,'🔄 Rotação Duplas'!H26),IF('⚙️ Configuração'!C30='🔄 Rotação Duplas'!D26,IF('🔄 Rotação Duplas'!I26="-",0,'🔄 Rotação Duplas'!I26),0))+IF('⚙️ Configuração'!C30='🔄 Rotação Duplas'!C27,IF('🔄 Rotação Duplas'!H27="-",0,'🔄 Rotação Duplas'!H27),IF('⚙️ Configuração'!C30='🔄 Rotação Duplas'!D27,IF('🔄 Rotação Duplas'!I27="-",0,'🔄 Rotação Duplas'!I27),0))+IF('⚙️ Configuração'!C30='🔄 Rotação Duplas'!C28,IF('🔄 Rotação Duplas'!H28="-",0,'🔄 Rotação Duplas'!H28),IF('⚙️ Configuração'!C30='🔄 Rotação Duplas'!D28,IF('🔄 Rotação Duplas'!I28="-",0,'🔄 Rotação Duplas'!I28),0))+IF('⚙️ Configuração'!C30='🔄 Rotação Duplas'!C29,IF('🔄 Rotação Duplas'!H29="-",0,'🔄 Rotação Duplas'!H29),IF('⚙️ Configuração'!C30='🔄 Rotação Duplas'!D29,IF('🔄 Rotação Duplas'!I29="-",0,'🔄 Rotação Duplas'!I29),0))+IF('⚙️ Configuração'!C30='🔄 Rotação Duplas'!C30,IF('🔄 Rotação Duplas'!H30="-",0,'🔄 Rotação Duplas'!H30),IF('⚙️ Configuração'!C30='🔄 Rotação Duplas'!D30,IF('🔄 Rotação Duplas'!I30="-",0,'🔄 Rotação Duplas'!I30),0))+IF('⚙️ Configuração'!C30='🔄 Rotação Duplas'!C31,IF('🔄 Rotação Duplas'!H31="-",0,'🔄 Rotação Duplas'!H31),IF('⚙️ Configuração'!C30='🔄 Rotação Duplas'!D31,IF('🔄 Rotação Duplas'!I31="-",0,'🔄 Rotação Duplas'!I31),0)) -> 0 | E6: =IF('⚙️ Configuração'!C30='🔄 Rotação Duplas'!C36,IF('🔄 Rotação Duplas'!H36="-",0,'🔄 Rotação Duplas'!H36),IF('⚙️ Configuração'!C30='🔄 Rotação Duplas'!D36,IF('🔄 Rotação Duplas'!I36="-",0,'🔄 Rotação Duplas'!I36),0))+IF('⚙️ Configuração'!C30='🔄 Rotação Duplas'!C37,IF('🔄 Rotação Duplas'!H37="-",0,'🔄 Rotação Duplas'!H37),IF('⚙️ Configuração'!C30='🔄 Rotação Duplas'!D37,IF('🔄 Rotação Duplas'!I37="-",0,'🔄 Rotação Duplas'!I37),0))+IF('⚙️ Configuração'!C30='🔄 Rotação Duplas'!C38,IF('🔄 Rotação Duplas'!H38="-",0,'🔄 Rotação Duplas'!H38),IF('⚙️ Configuração'!C30='🔄 Rotação Duplas'!D38,IF('🔄 Rotação Duplas'!I38="-",0,'🔄 Rotação Duplas'!I38),0))+IF('⚙️ Configuração'!C30='🔄 Rotação Duplas'!C39,IF('🔄 Rotação Duplas'!H39="-",0,'🔄 Rotação Duplas'!H39),IF('⚙️ Configuração'!C30='🔄 Rotação Duplas'!D39,IF('🔄 Rotação Duplas'!I39="-",0,'🔄 Rotação Duplas'!I39),0))+IF('⚙️ Configuração'!C30='🔄 Rotação Duplas'!C40,IF('🔄 Rotação Duplas'!H40="-",0,'🔄 Rotação Duplas'!H40),IF('⚙️ Configuração'!C30='🔄 Rotação Duplas'!D40,IF('🔄 Rotação Duplas'!I40="-",0,'🔄 Rotação Duplas'!I40),0))+IF('⚙️ Configuração'!C30='🔄 Rotação Duplas'!C41,IF('🔄 Rotação Duplas'!H41="-",0,'🔄 Rotação Duplas'!H41),IF('⚙️ Configuração'!C30='🔄 Rotação Duplas'!D41,IF('🔄 Rotação Duplas'!I41="-",0,'🔄 Rotação Duplas'!I41),0))+IF('⚙️ Configuração'!C30='🔄 Rotação Duplas'!C42,IF('🔄 Rotação Duplas'!H42="-",0,'🔄 Rotação Duplas'!H42),IF('⚙️ Configuração'!C30='🔄 Rotação Duplas'!D42,IF('🔄 Rotação Duplas'!I42="-",0,'🔄 Rotação Duplas'!I42),0))+IF('⚙️ Configuração'!C30='🔄 Rotação Duplas'!C43,IF('🔄 Rotação Duplas'!H43="-",0,'🔄 Rotação Duplas'!H43),IF('⚙️ Configuração'!C30='🔄 Rotação Duplas'!D43,IF('🔄 Rotação Duplas'!I43="-",0,'🔄 Rotação Duplas'!I43),0))+IF('⚙️ Configuração'!C30='🔄 Rotação Duplas'!C44,IF('🔄 Rotação Duplas'!H44="-",0,'🔄 Rotação Duplas'!H44),IF('⚙️ Configuração'!C30='🔄 Rotação Duplas'!D44,IF('🔄 Rotação Duplas'!I44="-",0,'🔄 Rotação Duplas'!I44),0))+IF('⚙️ Configuração'!C30='🔄 Rotação Duplas'!C45,IF('🔄 Rotação Duplas'!H45="-",0,'🔄 Rotação Duplas'!H45),IF('⚙️ Configuração'!C30='🔄 Rotação Duplas'!D45,IF('🔄 Rotação Duplas'!I45="-",0,'🔄 Rotação Duplas'!I45),0)) -> 0 | F6: =IF('⚙️ Configuração'!C30='🔄 Rotação Duplas'!C50,IF('🔄 Rotação Duplas'!H50="-",0,'🔄 Rotação Duplas'!H50),IF('⚙️ Configuração'!C30='🔄 Rotação Duplas'!D50,IF('🔄 Rotação Duplas'!I50="-",0,'🔄 Rotação Duplas'!I50),0))+IF('⚙️ Configuração'!C30='🔄 Rotação Duplas'!C51,IF('🔄 Rotação Duplas'!H51="-",0,'🔄 Rotação Duplas'!H51),IF('⚙️ Configuração'!C30='🔄 Rotação Duplas'!D51,IF('🔄 Rotação Duplas'!I51="-",0,'🔄 Rotação Duplas'!I51),0))+IF('⚙️ Configuração'!C30='🔄 Rotação Duplas'!C52,IF('🔄 Rotação Duplas'!H52="-",0,'🔄 Rotação Duplas'!H52),IF('⚙️ Configuração'!C30='🔄 Rotação Duplas'!D52,IF('🔄 Rotação Duplas'!I52="-",0,'🔄 Rotação Duplas'!I52),0))+IF('⚙️ Configuração'!C30='🔄 Rotação Duplas'!C53,IF('🔄 Rotação Duplas'!H53="-",0,'🔄 Rotação Duplas'!H53),IF('⚙️ Configuração'!C30='🔄 Rotação Duplas'!D53,IF('🔄 Rotação Duplas'!I53="-",0,'🔄 Rotação Duplas'!I53),0))+IF('⚙️ Configuração'!C30='🔄 Rotação Duplas'!C54,IF('🔄 Rotação Duplas'!H54="-",0,'🔄 Rotação Duplas'!H54),IF('⚙️ Configuração'!C30='🔄 Rotação Duplas'!D54,IF('🔄 Rotação Duplas'!I54="-",0,'🔄 Rotação Duplas'!I54),0))+IF('⚙️ Configuração'!C30='🔄 Rotação Duplas'!C55,IF('🔄 Rotação Duplas'!H55="-",0,'🔄 Rotação Duplas'!H55),IF('⚙️ Configuração'!C30='🔄 Rotação Duplas'!D55,IF('🔄 Rotação Duplas'!I55="-",0,'🔄 Rotação Duplas'!I55),0))+IF('⚙️ Configuração'!C30='🔄 Rotação Duplas'!C56,IF('🔄 Rotação Duplas'!H56="-",0,'🔄 Rotação Duplas'!H56),IF('⚙️ Configuração'!C30='🔄 Rotação Duplas'!D56,IF('🔄 Rotação Duplas'!I56="-",0,'🔄 Rotação Duplas'!I56),0))+IF('⚙️ Configuração'!C30='🔄 Rotação Duplas'!C57,IF('🔄 Rotação Duplas'!H57="-",0,'🔄 Rotação Duplas'!H57),IF('⚙️ Configuração'!C30='🔄 Rotação Duplas'!D57,IF('🔄 Rotação Duplas'!I57="-",0,'🔄 Rotação Duplas'!I57),0))+IF('⚙️ Configuração'!C30='🔄 Rotação Duplas'!C58,IF('🔄 Rotação Duplas'!H58="-",0,'🔄 Rotação Duplas'!H58),IF('⚙️ Configuração'!C30='🔄 Rotação Duplas'!D58,IF('🔄 Rotação Duplas'!I58="-",0,'🔄 Rotação Duplas'!I58),0))+IF('⚙️ Configuração'!C30='🔄 Rotação Duplas'!C59,IF('🔄 Rotação Duplas'!H59="-",0,'🔄 Rotação Duplas'!H59),IF('⚙️ Configuração'!C30='🔄 Rotação Duplas'!D59,IF('🔄 Rotação Duplas'!I59="-",0,'🔄 Rotação Duplas'!I59),0)) -> 0 | G6: =IF('⚙️ Configuração'!C30='🔄 Rotação Duplas'!C64,IF('🔄 Rotação Duplas'!H64="-",0,'🔄 Rotação Duplas'!H64),IF('⚙️ Configuração'!C30='🔄 Rotação Duplas'!D64,IF('🔄 Rotação Duplas'!I64="-",0,'🔄 Rotação Duplas'!I64),0))+IF('⚙️ Configuração'!C30='🔄 Rotação Duplas'!C65,IF('🔄 Rotação Duplas'!H65="-",0,'🔄 Rotação Duplas'!H65),IF('⚙️ Configuração'!C30='🔄 Rotação Duplas'!D65,IF('🔄 Rotação Duplas'!I65="-",0,'🔄 Rotação Duplas'!I65),0))+IF('⚙️ Configuração'!C30='🔄 Rotação Duplas'!C66,IF('🔄 Rotação Duplas'!H66="-",0,'🔄 Rotação Duplas'!H66),IF('⚙️ Configuração'!C30='🔄 Rotação Duplas'!D66,IF('🔄 Rotação Duplas'!I66="-",0,'🔄 Rotação Duplas'!I66),0))+IF('⚙️ Configuração'!C30='🔄 Rotação Duplas'!C67,IF('🔄 Rotação Duplas'!H67="-",0,'🔄 Rotação Duplas'!H67),IF('⚙️ Configuração'!C30='🔄 Rotação Duplas'!D67,IF('🔄 Rotação Duplas'!I67="-",0,'🔄 Rotação Duplas'!I67),0))+IF('⚙️ Configuração'!C30='🔄 Rotação Duplas'!C68,IF('🔄 Rotação Duplas'!H68="-",0,'🔄 Rotação Duplas'!H68),IF('⚙️ Configuração'!C30='🔄 Rotação Duplas'!D68,IF('🔄 Rotação Duplas'!I68="-",0,'🔄 Rotação Duplas'!I68),0))+IF('⚙️ Configuração'!C30='🔄 Rotação Duplas'!C69,IF('🔄 Rotação Duplas'!H69="-",0,'🔄 Rotação Duplas'!H69),IF('⚙️ Configuração'!C30='🔄 Rotação Duplas'!D69,IF('🔄 Rotação Duplas'!I69="-",0,'🔄 Rotação Duplas'!I69),0))+IF('⚙️ Configuração'!C30='🔄 Rotação Duplas'!C70,IF('🔄 Rotação Duplas'!H70="-",0,'🔄 Rotação Duplas'!H70),IF('⚙️ Configuração'!C30='🔄 Rotação Duplas'!D70,IF('🔄 Rotação Duplas'!I70="-",0,'🔄 Rotação Duplas'!I70),0))+IF('⚙️ Configuração'!C30='🔄 Rotação Duplas'!C71,IF('🔄 Rotação Duplas'!H71="-",0,'🔄 Rotação Duplas'!H71),IF('⚙️ Configuração'!C30='🔄 Rotação Duplas'!D71,IF('🔄 Rotação Duplas'!I71="-",0,'🔄 Rotação Duplas'!I71),0))+IF('⚙️ Configuração'!C30='🔄 Rotação Duplas'!C72,IF('🔄 Rotação Duplas'!H72="-",0,'🔄 Rotação Duplas'!H72),IF('⚙️ Configuração'!C30='🔄 Rotação Duplas'!D72,IF('🔄 Rotação Duplas'!I72="-",0,'🔄 Rotação Duplas'!I72),0))+IF('⚙️ Configuração'!C30='🔄 Rotação Duplas'!C73,IF('🔄 Rotação Duplas'!H73="-",0,'🔄 Rotação Duplas'!H73),IF('⚙️ Configuração'!C30='🔄 Rotação Duplas'!D73,IF('🔄 Rotação Duplas'!I73="-",0,'🔄 Rotação Duplas'!I73),0)) -> 0 | H6: =IF('⚙️ Configuração'!C30='🔄 Rotação Duplas'!C78,IF('🔄 Rotação Duplas'!H78="-",0,'🔄 Rotação Duplas'!H78),IF('⚙️ Configuração'!C30='🔄 Rotação Duplas'!D78,IF('🔄 Rotação Duplas'!I78="-",0,'🔄 Rotação Duplas'!I78),0))+IF('⚙️ Configuração'!C30='🔄 Rotação Duplas'!C79,IF('🔄 Rotação Duplas'!H79="-",0,'🔄 Rotação Duplas'!H79),IF('⚙️ Configuração'!C30='🔄 Rotação Duplas'!D79,IF('🔄 Rotação Duplas'!I79="-",0,'🔄 Rotação Duplas'!I79),0))+IF('⚙️ Configuração'!C30='🔄 Rotação Duplas'!C80,IF('🔄 Rotação Duplas'!H80="-",0,'🔄 Rotação Duplas'!H80),IF('⚙️ Configuração'!C30='🔄 Rotação Duplas'!D80,IF('🔄 Rotação Duplas'!I80="-",0,'🔄 Rotação Duplas'!I80),0))+IF('⚙️ Configuração'!C30='🔄 Rotação Duplas'!C81,IF('🔄 Rotação Duplas'!H81="-",0,'🔄 Rotação Duplas'!H81),IF('⚙️ Configuração'!C30='🔄 Rotação Duplas'!D81,IF('🔄 Rotação Duplas'!I81="-",0,'🔄 Rotação Duplas'!I81),0))+IF('⚙️ Configuração'!C30='🔄 Rotação Duplas'!C82,IF('🔄 Rotação Duplas'!H82="-",0,'🔄 Rotação Duplas'!H82),IF('⚙️ Configuração'!C30='🔄 Rotação Duplas'!D82,IF('🔄 Rotação Duplas'!I82="-",0,'🔄 Rotação Duplas'!I82),0))+IF('⚙️ Configuração'!C30='🔄 Rotação Duplas'!C83,IF('🔄 Rotação Duplas'!H83="-",0,'🔄 Rotação Duplas'!H83),IF('⚙️ Configuração'!C30='🔄 Rotação Duplas'!D83,IF('🔄 Rotação Duplas'!I83="-",0,'🔄 Rotação Duplas'!I83),0))+IF('⚙️ Configuração'!C30='🔄 Rotação Duplas'!C84,IF('🔄 Rotação Duplas'!H84="-",0,'🔄 Rotação Duplas'!H84),IF('⚙️ Configuração'!C30='🔄 Rotação Duplas'!D84,IF('🔄 Rotação Duplas'!I84="-",0,'🔄 Rotação Duplas'!I84),0))+IF('⚙️ Configuração'!C30='🔄 Rotação Duplas'!C85,IF('🔄 Rotação Duplas'!H85="-",0,'🔄 Rotação Duplas'!H85),IF('⚙️ Configuração'!C30='🔄 Rotação Duplas'!D85,IF('🔄 Rotação Duplas'!I85="-",0,'🔄 Rotação Duplas'!I85),0))+IF('⚙️ Configuração'!C30='🔄 Rotação Duplas'!C86,IF('🔄 Rotação Duplas'!H86="-",0,'🔄 Rotação Duplas'!H86),IF('⚙️ Configuração'!C30='🔄 Rotação Duplas'!D86,IF('🔄 Rotação Duplas'!I86="-",0,'🔄 Rotação Duplas'!I86),0))+IF('⚙️ Configuração'!C30='🔄 Rotação Duplas'!C87,IF('🔄 Rotação Duplas'!H87="-",0,'🔄 Rotação Duplas'!H87),IF('⚙️ Configuração'!C30='🔄 Rotação Duplas'!D87,IF('🔄 Rotação Duplas'!I87="-",0,'🔄 Rotação Duplas'!I87),0)) -> 0 | I6: =IF('⚙️ Configuração'!C30='🔄 Rotação Duplas'!C92,IF('🔄 Rotação Duplas'!H92="-",0,'🔄 Rotação Duplas'!H92),IF('⚙️ Configuração'!C30='🔄 Rotação Duplas'!D92,IF('🔄 Rotação Duplas'!I92="-",0,'🔄 Rotação Duplas'!I92),0))+IF('⚙️ Configuração'!C30='🔄 Rotação Duplas'!C93,IF('🔄 Rotação Duplas'!H93="-",0,'🔄 Rotação Duplas'!H93),IF('⚙️ Configuração'!C30='🔄 Rotação Duplas'!D93,IF('🔄 Rotação Duplas'!I93="-",0,'🔄 Rotação Duplas'!I93),0))+IF('⚙️ Configuração'!C30='🔄 Rotação Duplas'!C94,IF('🔄 Rotação Duplas'!H94="-",0,'🔄 Rotação Duplas'!H94),IF('⚙️ Configuração'!C30='🔄 Rotação Duplas'!D94,IF('🔄 Rotação Duplas'!I94="-",0,'🔄 Rotação Duplas'!I94),0))+IF('⚙️ Configuração'!C30='🔄 Rotação Duplas'!C95,IF('🔄 Rotação Duplas'!H95="-",0,'🔄 Rotação Duplas'!H95),IF('⚙️ Configuração'!C30='🔄 Rotação Duplas'!D95,IF('🔄 Rotação Duplas'!I95="-",0,'🔄 Rotação Duplas'!I95),0))+IF('⚙️ Configuração'!C30='🔄 Rotação Duplas'!C96,IF('🔄 Rotação Duplas'!H96="-",0,'🔄 Rotação Duplas'!H96),IF('⚙️ Configuração'!C30='🔄 Rotação Duplas'!D96,IF('🔄 Rotação Duplas'!I96="-",0,'🔄 Rotação Duplas'!I96),0))+IF('⚙️ Configuração'!C30='🔄 Rotação Duplas'!C97,IF('🔄 Rotação Duplas'!H97="-",0,'🔄 Rotação Duplas'!H97),IF('⚙️ Configuração'!C30='🔄 Rotação Duplas'!D97,IF('🔄 Rotação Duplas'!I97="-",0,'🔄 Rotação Duplas'!I97),0))+IF('⚙️ Configuração'!C30='🔄 Rotação Duplas'!C98,IF('🔄 Rotação Duplas'!H98="-",0,'🔄 Rotação Duplas'!H98),IF('⚙️ Configuração'!C30='🔄 Rotação Duplas'!D98,IF('🔄 Rotação Duplas'!I98="-",0,'🔄 Rotação Duplas'!I98),0))+IF('⚙️ Configuração'!C30='🔄 Rotação Duplas'!C99,IF('🔄 Rotação Duplas'!H99="-",0,'🔄 Rotação Duplas'!H99),IF('⚙️ Configuração'!C30='🔄 Rotação Duplas'!D99,IF('🔄 Rotação Duplas'!I99="-",0,'🔄 Rotação Duplas'!I99),0))+IF('⚙️ Configuração'!C30='🔄 Rotação Duplas'!C100,IF('🔄 Rotação Duplas'!H100="-",0,'🔄 Rotação Duplas'!H100),IF('⚙️ Configuração'!C30='🔄 Rotação Duplas'!D100,IF('🔄 Rotação Duplas'!I100="-",0,'🔄 Rotação Duplas'!I100),0))+IF('⚙️ Configuração'!C30='🔄 Rotação Duplas'!C101,IF('🔄 Rotação Duplas'!H101="-",0,'🔄 Rotação Duplas'!H101),IF('⚙️ Configuração'!C30='🔄 Rotação Duplas'!D101,IF('🔄 Rotação Duplas'!I101="-",0,'🔄 Rotação Duplas'!I101),0)) -> 0 | J6: =IF('⚙️ Configuração'!C30='🔄 Rotação Duplas'!C106,IF('🔄 Rotação Duplas'!H106="-",0,'🔄 Rotação Duplas'!H106),IF('⚙️ Configuração'!C30='🔄 Rotação Duplas'!D106,IF('🔄 Rotação Duplas'!I106="-",0,'🔄 Rotação Duplas'!I106),0))+IF('⚙️ Configuração'!C30='🔄 Rotação Duplas'!C107,IF('🔄 Rotação Duplas'!H107="-",0,'🔄 Rotação Duplas'!H107),IF('⚙️ Configuração'!C30='🔄 Rotação Duplas'!D107,IF('🔄 Rotação Duplas'!I107="-",0,'🔄 Rotação Duplas'!I107),0))+IF('⚙️ Configuração'!C30='🔄 Rotação Duplas'!C108,IF('🔄 Rotação Duplas'!H108="-",0,'🔄 Rotação Duplas'!H108),IF('⚙️ Configuração'!C30='🔄 Rotação Duplas'!D108,IF('🔄 Rotação Duplas'!I108="-",0,'🔄 Rotação Duplas'!I108),0))+IF('⚙️ Configuração'!C30='🔄 Rotação Duplas'!C109,IF('🔄 Rotação Duplas'!H109="-",0,'🔄 Rotação Duplas'!H109),IF('⚙️ Configuração'!C30='🔄 Rotação Duplas'!D109,IF('🔄 Rotação Duplas'!I109="-",0,'🔄 Rotação Duplas'!I109),0))+IF('⚙️ Configuração'!C30='🔄 Rotação Duplas'!C110,IF('🔄 Rotação Duplas'!H110="-",0,'🔄 Rotação Duplas'!H110),IF('⚙️ Configuração'!C30='🔄 Rotação Duplas'!D110,IF('🔄 Rotação Duplas'!I110="-",0,'🔄 Rotação Duplas'!I110),0))+IF('⚙️ Configuração'!C30='🔄 Rotação Duplas'!C111,IF('🔄 Rotação Duplas'!H111="-",0,'🔄 Rotação Duplas'!H111),IF('⚙️ Configuração'!C30='🔄 Rotação Duplas'!D111,IF('🔄 Rotação Duplas'!I111="-",0,'🔄 Rotação Duplas'!I111),0))+IF('⚙️ Configuração'!C30='🔄 Rotação Duplas'!C112,IF('🔄 Rotação Duplas'!H112="-",0,'🔄 Rotação Duplas'!H112),IF('⚙️ Configuração'!C30='🔄 Rotação Duplas'!D112,IF('🔄 Rotação Duplas'!I112="-",0,'🔄 Rotação Duplas'!I112),0))+IF('⚙️ Configuração'!C30='🔄 Rotação Duplas'!C113,IF('🔄 Rotação Duplas'!H113="-",0,'🔄 Rotação Duplas'!H113),IF('⚙️ Configuração'!C30='🔄 Rotação Duplas'!D113,IF('🔄 Rotação Duplas'!I113="-",0,'🔄 Rotação Duplas'!I113),0))+IF('⚙️ Configuração'!C30='🔄 Rotação Duplas'!C114,IF('🔄 Rotação Duplas'!H114="-",0,'🔄 Rotação Duplas'!H114),IF('⚙️ Configuração'!C30='🔄 Rotação Duplas'!D114,IF('🔄 Rotação Duplas'!I114="-",0,'🔄 Rotação Duplas'!I114),0))+IF('⚙️ Configuração'!C30='🔄 Rotação Duplas'!C115,IF('🔄 Rotação Duplas'!H115="-",0,'🔄 Rotação Duplas'!H115),IF('⚙️ Configuração'!C30='🔄 Rotação Duplas'!D115,IF('🔄 Rotação Duplas'!I115="-",0,'🔄 Rotação Duplas'!I115),0)) -> 0 | K6: =SUM(C6:J6) -> 43 | L6: =SUMIF('📋 Registo Diário'!$D$7:$D$646,'⚙️ Configuração'!C30,'📋 Registo Diário'!$Q$7:$Q$646) -> 45 | M6: =K6+L6 -> 88
